<?xml version="1.0"?>
<robot xmlns:xacro="http://www.ros.org/wiki/xacro" name="diff_drive_robot">

  <!-- ========================== PROPERTIES ========================== -->
  <xacro:property name="chassis_length" value="0.4"/>
  <xacro:property name="chassis_width"  value="0.3"/>
  <xacro:property name="chassis_height" value="0.15"/>
  <xacro:property name="chassis_mass"   value="5.0"/>

  <xacro:property name="wheel_radius"   value="0.07"/>
  <xacro:property name="wheel_width"    value="0.04"/>
  <xacro:property name="wheel_mass"     value="0.5"/>

  <xacro:property name="caster_radius"  value="0.035"/>
  <xacro:property name="caster_mass"    value="0.2"/>

  <xacro:property name="lidar_size"     value="0.05"/>
  <xacro:property name="lidar_mass"     value="0.1"/>

  <!-- ========================== MATERIALS ========================== -->
  <material name="blue">
    <color rgba="0.2 0.2 0.8 1.0"/>
  </material>
  <material name="black">
    <color rgba="0.1 0.1 0.1 1.0"/>
  </material>
  <material name="red">
    <color rgba="0.8 0.2 0.2 1.0"/>
  </material>
  <material name="grey">
    <color rgba="0.5 0.5 0.5 1.0"/>
  </material>

  <!-- ========================== INERTIA MACROS ========================== -->
  <xacro:macro name="box_inertia" params="m x y z">
    <inertial>
      <mass value="${m}"/>
      <inertia ixx="${m*(y*y+z*z)/12}" ixy="0" ixz="0"
               iyy="${m*(x*x+z*z)/12}" iyz="0"
               izz="${m*(x*x+y*y)/12}"/>
    </inertial>
  </xacro:macro>

  <xacro:macro name="cylinder_inertia" params="m r h">
    <inertial>
      <mass value="${m}"/>
      <inertia ixx="${m*(3*r*r+h*h)/12}" ixy="0" ixz="0"
               iyy="${m*(3*r*r+h*h)/12}" iyz="0"
               izz="${m*r*r/2}"/>
    </inertial>
  </xacro:macro>

  <xacro:macro name="sphere_inertia" params="m r">
    <inertial>
      <mass value="${m}"/>
      <inertia ixx="${2*m*r*r/5}" ixy="0" ixz="0"
               iyy="${2*m*r*r/5}" iyz="0"
               izz="${2*m*r*r/5}"/>
    </inertial>
  </xacro:macro>

  <!-- ========================== BASE FOOTPRINT ========================== -->
  <link name="base_footprint"/>

  <joint name="base_joint" type="fixed">
    <parent link="base_footprint"/>
    <child  link="base_link"/>
    <origin xyz="0 0 ${wheel_radius}" rpy="0 0 0"/>
  </joint>

  <!-- ========================== CHASSIS (base_link) ========================== -->
  <link name="base_link">
    <visual>
      <geometry>
        <box size="${chassis_length} ${chassis_width} ${chassis_height}"/>
      </geometry>
      <origin xyz="0 0 ${chassis_height/2}" rpy="0 0 0"/>
      <material name="blue"/>
    </visual>
    <collision>
      <geometry>
        <box size="${chassis_length} ${chassis_width} ${chassis_height}"/>
      </geometry>
      <origin xyz="0 0 ${chassis_height/2}" rpy="0 0 0"/>
    </collision>
    <xacro:box_inertia m="${chassis_mass}" x="${chassis_length}" y="${chassis_width}" z="${chassis_height}"/>
  </link>

  <gazebo reference="base_link">
    <material>Gazebo/Blue</material>
  </gazebo>

  <!-- ========================== WHEEL MACRO ========================== -->
  <xacro:macro name="drive_wheel" params="prefix y_offset">
    <link name="${prefix}_wheel">
      <visual>
        <geometry>
          <cylinder radius="${wheel_radius}" length="${wheel_width}"/>
        </geometry>
        <material name="black"/>
      </visual>
      <collision>
        <geometry>
          <cylinder radius="${wheel_radius}" length="${wheel_width}"/>
        </geometry>
      </collision>
      <xacro:cylinder_inertia m="${wheel_mass}" r="${wheel_radius}" h="${wheel_width}"/>
    </link>

    <joint name="${prefix}_wheel_joint" type="continuous">
      <parent link="base_link"/>
      <child  link="${prefix}_wheel"/>
      <origin xyz="0 ${y_offset} 0" rpy="${-pi/2} 0 0"/>
      <axis xyz="0 0 1"/>
      <dynamics friction="1.0" damping="0.1"/>
    </joint>

    <gazebo reference="${prefix}_wheel">
      <material>Gazebo/DarkGrey</material>
      <mu1>1.0</mu1>
      <mu2>1.0</mu2>
    </gazebo>
  </xacro:macro>

  <xacro:drive_wheel prefix="left"  y_offset="${chassis_width/2 + wheel_width/2}"/>
  <xacro:drive_wheel prefix="right" y_offset="${-(chassis_width/2 + wheel_width/2)}"/>

  <!-- ========================== CASTER WHEEL ========================== -->
  <link name="caster_wheel">
    <visual>
      <geometry>
        <sphere radius="${caster_radius}"/>
      </geometry>
      <material name="grey"/>
    </visual>
    <collision>
      <geometry>
        <sphere radius="${caster_radius}"/>
      </geometry>
    </collision>
    <xacro:sphere_inertia m="${caster_mass}" r="${caster_radius}"/>
  </link>

  <joint name="caster_joint" type="fixed">
    <parent link="base_link"/>
    <child  link="caster_wheel"/>
    <origin xyz="${-chassis_length/2 + caster_radius} 0 ${-(wheel_radius - caster_radius)}" rpy="0 0 0"/>
  </joint>

  <gazebo reference="caster_wheel">
    <material>Gazebo/Grey</material>
    <mu1>0.0</mu1>
    <mu2>0.0</mu2>
  </gazebo>

  <!-- ========================== LIDAR SENSOR ========================== -->
  <link name="lidar_link">
    <visual>
      <geometry>
        <cylinder radius="${lidar_size}" length="${lidar_size}"/>
      </geometry>
      <material name="red"/>
    </visual>
    <collision>
      <geometry>
        <cylinder radius="${lidar_size}" length="${lidar_size}"/>
      </geometry>
    </collision>
    <xacro:cylinder_inertia m="${lidar_mass}" r="${lidar_size}" h="${lidar_size}"/>
  </link>

  <joint name="lidar_joint" type="fixed">
    <parent link="base_link"/>
    <child  link="lidar_link"/>
    <origin xyz="0 0 ${chassis_height + lidar_size/2}" rpy="0 0 0"/>
  </joint>

  <gazebo reference="lidar_link">
    <material>Gazebo/Red</material>
    <sensor type="ray" name="lidar_sensor">
      <pose>0 0 0 0 0 0</pose>
      <visualize>true</visualize>
      <update_rate>10</update_rate>
      <ray>
        <scan>
          <horizontal>
            <samples>360</samples>
            <resolution>1</resolution>
            <min_angle>-3.14159265</min_angle>
            <max_angle>3.14159265</max_angle>
          </horizontal>
        </scan>
        <range>
          <min>0.12</min>
          <max>12.0</max>
          <resolution>0.01</resolution>
        </range>
        <noise>
          <type>gaussian</type>
          <mean>0.0</mean>
          <stddev>0.01</stddev>
        </noise>
      </ray>
      <plugin name="gazebo_ros_lidar" filename="libgazebo_ros_ray_sensor.so">
        <ros>
          <remapping>~/out:=scan</remapping>
        </ros>
        <output_type>sensor_msgs/LaserScan</output_type>
        <frame_name>lidar_link</frame_name>
      </plugin>
    </sensor>
  </gazebo>

  <!-- ========================== DIFFERENTIAL DRIVE PLUGIN ========================== -->
  <gazebo>
    <plugin name="diff_drive_controller" filename="libgazebo_ros_diff_drive.so">
      <ros>
        <namespace>/</namespace>
      </ros>

      <!-- Wheel joints -->
      <left_joint>left_wheel_joint</left_joint>
      <right_joint>right_wheel_joint</right_joint>

      <!-- Kinematics -->
      <wheel_separation>${chassis_width + wheel_width}</wheel_separation>
      <wheel_diameter>${2 * wheel_radius}</wheel_diameter>

      <!-- Limits -->
      <max_wheel_torque>20</max_wheel_torque>
      <max_wheel_acceleration>1.0</max_wheel_acceleration>

      <!-- Output -->
      <command_topic>cmd_vel</command_topic>
      <odometry_topic>odom</odometry_topic>
      <odometry_frame>odom</odometry_frame>
      <robot_base_frame>base_footprint</robot_base_frame>

      <publish_odom>true</publish_odom>
      <publish_odom_tf>true</publish_odom_tf>
      <publish_wheel_tf>true</publish_wheel_tf>
      <publish_joint_state>true</publish_joint_state>

      <update_rate>30</update_rate>
    </plugin>
  </gazebo>

</robot>
